---
title: promise
categories: 
  - ES6
tags: 
  - ES6
  - promise
---

记录一下需要记忆的点
## finally的实现方式

虽然看起来很简单，但是也值得思索

```
Promise.prototype.myFinally = function (callback) {
  其实这个P === Promise // true
  let P = this.constructor;
  // finally其实返回了一个then 在resolve和reject的情况下 都会触发
  return this.then(
    value  => P.resolve(callback()).then(() => value),
    // 这里继续扔出了一个错误，避免下一个catch无法捕获到错误
    reason => P.resolve(callback()).then(() => { throw reason })
  );
};
```

从上边的代码，我们可以得知

- 错误捕获到后，就不会继续冒泡了，也就是不会被后面的catch捕获，所以上边代码加了一个throw reson

- 从上面的实现还可以看到，`finally`方法总是会返回原来的值，注意下述代码

  - ```
    const p2 = new Promise(function (resolve, reject) {
          setTimeout(() => resolve("11111"), 1000)
        })
        Promise.prototype.myFinally = function (callback) {
          let P = this.constructor;
          return this.then(
            value  => P.resolve(callback()).then(() => value),
            reason => P.resolve(callback()).then(() => { throw reason })
          );
        };
        p2.myFinally(() => {
    
        }).then(res => {
          console.log(res); // 1111
        })
    ```

    也就意味着在promise中穿插finally 并不会有副作用

- // TODO `P.resolve(callback()).then(() => value)` 为什么需要这么长呢

  

## 面试手写promise

### 面试够用版

> 没实现异步吧 我觉得

> 来源：[实现一个完美符合Promise/A+规范的Promise](https://link.juejin.cn?target=https%3A%2F%2Fgithub.com%2Fforthealllight%2Fblog%2Fissues%2F4)

```
function myPromise(constructor){
    let self=this;
    self.status="pending" //定义状态改变前的初始状态
    self.value=undefined;//定义状态为resolved的时候的状态
    self.reason=undefined;//定义状态为rejected的时候的状态
    function resolve(value){
        //两个==="pending"，保证了状态的改变是不可逆的
       if(self.status==="pending"){
          self.value=value;
          self.status="resolved";
       }
    }
    function reject(reason){
        //两个==="pending"，保证了状态的改变是不可逆的
       if(self.status==="pending"){
          self.reason=reason;
          self.status="rejected";
       }
    }
    //捕获构造异常
    try{
       constructor(resolve,reject);
    }catch(e){
       reject(e);
    }
}
myPromise.prototype.then=function(onFullfilled,onRejected){
   let self=this;
   switch(self.status){
      case "resolved":
        onFullfilled(self.value);
        break;
      case "rejected":
        onRejected(self.reason);
        break;
      default:       
   }
}

```

### 大厂专供版

直接贴出来吧，这个版本还算好理解

```
const PENDING = "pending";
const FULFILLED = "fulfilled";
const REJECTED = "rejected";

function Promise(excutor) {
    let that = this; // 缓存当前promise实例对象
    that.status = PENDING; // 初始状态
    that.value = undefined; // fulfilled状态时 返回的信息
    that.reason = undefined; // rejected状态时 拒绝的原因
    that.onFulfilledCallbacks = []; // 存储fulfilled状态对应的onFulfilled函数
    that.onRejectedCallbacks = []; // 存储rejected状态对应的onRejected函数

    function resolve(value) { // value成功态时接收的终值
        if(value instanceof Promise) {
            return value.then(resolve, reject);
        }
        // 实践中要确保 onFulfilled 和 onRejected 方法异步执行，且应该在 then 方法被调用的那一轮事件循环之后的新执行栈中执行。
        setTimeout(() => {
            // 调用resolve 回调对应onFulfilled函数
            if (that.status === PENDING) {
                // 只能由pending状态 => fulfilled状态 (避免调用多次resolve reject)
                that.status = FULFILLED;
                that.value = value;
                that.onFulfilledCallbacks.forEach(cb => cb(that.value));
            }
        });
    }
    function reject(reason) { // reason失败态时接收的拒因
        setTimeout(() => {
            // 调用reject 回调对应onRejected函数
            if (that.status === PENDING) {
                // 只能由pending状态 => rejected状态 (避免调用多次resolve reject)
                that.status = REJECTED;
                that.reason = reason;
                that.onRejectedCallbacks.forEach(cb => cb(that.reason));
            }
        });
    }

    // 捕获在excutor执行器中抛出的异常
    // new Promise((resolve, reject) => {
    //     throw new Error('error in excutor')
    // })
    try {
        excutor(resolve, reject);
    } catch (e) {
        reject(e);
    }
}

Promise.prototype.then = function(onFulfilled, onRejected) {
    const that = this;
    let newPromise;
    // 处理参数默认值 保证参数后续能够继续执行
    onFulfilled =
        typeof onFulfilled === "function" ? onFulfilled : value => value;
    onRejected =
        typeof onRejected === "function" ? onRejected : reason => {
            throw reason;
        };
    if (that.status === FULFILLED) { // 成功态
        return newPromise = new Promise((resolve, reject) => {
            setTimeout(() => {
                try{
                    let x = onFulfilled(that.value);
                    resolvePromise(newPromise, x, resolve, reject); // 新的promise resolve 上一个onFulfilled的返回值
                } catch(e) {
                    reject(e); // 捕获前面onFulfilled中抛出的异常 then(onFulfilled, onRejected);
                }
            });
        })
    }

    if (that.status === REJECTED) { // 失败态
        return newPromise = new Promise((resolve, reject) => {
            setTimeout(() => {
                try {
                    let x = onRejected(that.reason);
                    resolvePromise(newPromise, x, resolve, reject);
                } catch(e) {
                    reject(e);
                }
            });
        });
    }

    if (that.status === PENDING) { // 等待态
        // 当异步调用resolve/rejected时 将onFulfilled/onRejected收集暂存到集合中
        return newPromise = new Promise((resolve, reject) => {
            that.onFulfilledCallbacks.push((value) => {
                try {
                    let x = onFulfilled(value);
                    resolvePromise(newPromise, x, resolve, reject);
                } catch(e) {
                    reject(e);
                }
            });
            that.onRejectedCallbacks.push((reason) => {
                try {
                    let x = onRejected(reason);
                    resolvePromise(newPromise, x, resolve, reject);
                } catch(e) {
                    reject(e);
                }
            });
        });
    }
};
```